<sdf version='1.4'>
  <world name='default'>
    <light name='sun' type='directional'>
      <cast_shadows>1</cast_shadows>
      <pose>0 0 10 0 -0 0</pose>
      <diffuse>0.8 0.8 0.8 1</diffuse>
      <specular>0.2 0.2 0.2 1</specular>
      <attenuation>
        <range>1000</range>
        <constant>0.9</constant>
        <linear>0.01</linear>
        <quadratic>0.001</quadratic>
      </attenuation>
      <direction>-0.5 0.1 -0.9</direction>
    </light>
    <model name='ground_plane'>
      <static>1</static>
      <link name='link'>
        <collision name='collision'>
          <geometry>
            <plane>
              <normal>0 0 1</normal>
              <size>100 100</size>
            </plane>
          </geometry>
          <surface>
            <friction>
              <ode>
                <mu>100</mu>
                <mu2>50</mu2>
              </ode>
            </friction>
            <bounce/>
            <contact>
              <ode/>
            </contact>
          </surface>
          <max_contacts>10</max_contacts>
        </collision>
        <visual name='visual'>
          <cast_shadows>0</cast_shadows>
          <geometry>
            <plane>
              <normal>0 0 1</normal>
              <size>100 100</size>
            </plane>
          </geometry>
          <material>
            <script>
              <uri>file://media/materials/scripts/gazebo.material</uri>
              <name>Gazebo/Grey</name>
            </script>
          </material>
        </visual>
        <velocity_decay>
          <linear>0</linear>
          <angular>0</angular>
        </velocity_decay>
        <self_collide>0</self_collide>
        <kinematic>0</kinematic>
        <gravity>1</gravity>
      </link>
    </model>
    <physics type='ode'>
      <max_step_size>0.001</max_step_size>
      <real_time_factor>1</real_time_factor>
      <real_time_update_rate>1000</real_time_update_rate>
      <gravity>0 0 -9.8</gravity>
    </physics>
    <scene>
      <ambient>0.4 0.4 0.4 1</ambient>
      <background>0.7 0.7 0.7 1</background>
      <shadows>1</shadows>
    </scene>
    <spherical_coordinates>
      <surface_model>EARTH_WGS84</surface_model>
      <latitude_deg>0</latitude_deg>
      <longitude_deg>0</longitude_deg>
      <elevation>0</elevation>
      <heading_deg>0</heading_deg>
    </spherical_coordinates>
    <model name='create'>
      <link name='base'>
        <inertial>
          <pose>0.001453 -0.000453 0.029787 0 -0 0</pose>
          <inertia>
            <ixx>0.05864</ixx>
            <ixy>0.000124</ixy>
            <ixz>0.000615</ixz>
            <iyy>0.058786</iyy>
            <iyz>1.4e-05</iyz>
            <izz>1.53244</izz>
          </inertia>
          <mass>2.234</mass>
        </inertial>
        <collision name='base_collision'>
          <pose>0 0 0.0478 0 -0 0</pose>
          <geometry>
            <cylinder>
              <radius>0.016495</radius>
              <length>0.061163</length>
            </cylinder>
          </geometry>
          <max_contacts>10</max_contacts>
          <surface>
            <bounce/>
            <friction>
              <ode/>
            </friction>
            <contact>
              <ode/>
            </contact>
          </surface>
        </collision>
        <visual name='base_visual'>
          <pose>0 0 0.0478 0 -0 0</pose>
          <geometry>
            <mesh>
              <uri>model://create/meshes/create_body.dae</uri>
            </mesh>
          </geometry>
        </visual>
        <collision name='front_wheel_collision'>
          <pose>0.13 0 0.017 -5.76279e-13 1.5707 1.5707</pose>
          <geometry>
            <sphere>
              <radius>0.018</radius>
            </sphere>
          </geometry>
          <surface>
            <friction>
              <ode>
                <mu>0</mu>
                <mu2>0</mu2>
                <fdir1>0 0 0</fdir1>
                <slip1>0</slip1>
                <slip2>0</slip2>
              </ode>
            </friction>
            <bounce/>
            <contact>
              <ode/>
            </contact>
          </surface>
          <max_contacts>10</max_contacts>
        </collision>
        <visual name='front_wheel_visual'>
          <pose>0.13 0 0.017 -5.76279e-13 1.5707 1.5707</pose>
          <geometry>
            <sphere>
              <radius>0.009</radius>
            </sphere>
          </geometry>
        </visual>
        <collision name='rear_wheel_collision'>
          <pose>-0.13 0 0.017 -5.76279e-13 1.5707 1.5707</pose>
          <geometry>
            <sphere>
              <radius>0.015</radius>
            </sphere>
          </geometry>
          <surface>
            <friction>
              <ode>
                <mu>0</mu>
                <mu2>0</mu2>
                <fdir1>0 0 0</fdir1>
                <slip1>0</slip1>
                <slip2>0</slip2>
              </ode>
            </friction>
            <bounce/>
            <contact>
              <ode/>
            </contact>
          </surface>
          <max_contacts>10</max_contacts>
        </collision>
        <visual name='rear_wheel_visual'>
          <pose>-0.13 0 0.017 -5.76279e-13 1.5707 1.5707</pose>
          <geometry>
            <sphere>
              <radius>0.0075</radius>
            </sphere>
          </geometry>
        </visual>
        <sensor name='left_cliff_sensor' type='ray'>
          <pose>0.07 0.14 0.027 0 1.57079 0</pose>
          <ray>
            <scan>
              <horizontal>
                <samples>1</samples>
                <resolution>1</resolution>
                <min_angle>0</min_angle>
                <max_angle>0</max_angle>
              </horizontal>
            </scan>
            <range>
              <min>0.01</min>
              <max>0.04</max>
              <resolution>0.1</resolution>
            </range>
          </ray>
        </sensor>
        <sensor name='leftfront_cliff_sensor' type='ray'>
          <pose>0.15 0.04 0.027 0 1.57079 0</pose>
          <ray>
            <scan>
              <horizontal>
                <samples>1</samples>
                <resolution>1</resolution>
                <min_angle>0</min_angle>
                <max_angle>0</max_angle>
              </horizontal>
            </scan>
            <range>
              <min>0.01</min>
              <max>0.04</max>
              <resolution>0.1</resolution>
            </range>
          </ray>
        </sensor>
        <sensor name='right_cliff_sensor' type='ray'>
          <pose>0.07 -0.14 0.027 0 1.57079 0</pose>
          <ray>
            <scan>
              <horizontal>
                <samples>1</samples>
                <resolution>1</resolution>
                <min_angle>0</min_angle>
                <max_angle>0</max_angle>
              </horizontal>
            </scan>
            <range>
              <min>0.01</min>
              <max>0.04</max>
              <resolution>0.1</resolution>
            </range>
          </ray>
        </sensor>
        <sensor name='rightfront_cliff_sensor' type='ray'>
          <pose>0.15 -0.04 0.027 0 1.57079 0</pose>
          <ray>
            <scan>
              <horizontal>
                <samples>1</samples>
                <resolution>1</resolution>
                <min_angle>0</min_angle>
                <max_angle>0</max_angle>
              </horizontal>
            </scan>
            <range>
              <min>0.01</min>
              <max>0.04</max>
              <resolution>0.1</resolution>
            </range>
          </ray>
        </sensor>
        <sensor name='wall_sensor' type='ray'>
          <pose>0.09 -0.12 0.059 0 0 -1</pose>
          <ray>
            <scan>
              <horizontal>
                <samples>1</samples>
                <resolution>1</resolution>
                <min_angle>0</min_angle>
                <max_angle>0</max_angle>
              </horizontal>
            </scan>
            <range>
              <min>0.016</min>
              <max>0.04</max>
              <resolution>0.1</resolution>
            </range>
          </ray>
        </sensor>
        <velocity_decay>
          <linear>0</linear>
          <angular>0</angular>
        </velocity_decay>
        <self_collide>0</self_collide>
        <kinematic>0</kinematic>
        <gravity>1</gravity>
      </link>
      <link name='left_wheel'>
        <pose>0 0.13 0.032 0 -0 0</pose>
        <inertial>
          <inertia>
            <ixx>0.001</ixx>
            <ixy>0</ixy>
            <ixz>0</ixz>
            <iyy>0.001</iyy>
            <iyz>0</iyz>
            <izz>0.001</izz>
          </inertia>
          <mass>0.01</mass>
        </inertial>
        <collision name='collision'>
          <pose>0 0 0 -5.76279e-13 1.5707 1.5707</pose>
          <geometry>
            <cylinder>
              <radius>0.033</radius>
              <length>0.023</length>
            </cylinder>
          </geometry>
          <surface>
            <friction>
              <ode>
                <mu>10</mu>
                <mu2>10</mu2>
                <fdir1>0 0 0</fdir1>
                <slip1>0</slip1>
                <slip2>0</slip2>
              </ode>
            </friction>
            <bounce/>
            <contact>
              <ode/>
            </contact>
          </surface>
          <max_contacts>10</max_contacts>
        </collision>
        <visual name='visual'>
          <pose>0 0 0 -5.76279e-13 1.5707 1.5707</pose>
          <geometry>
            <cylinder>
              <radius>0.033</radius>
              <length>0.023</length>
            </cylinder>
          </geometry>
        </visual>
        <velocity_decay>
          <linear>0</linear>
          <angular>0</angular>
        </velocity_decay>
        <self_collide>0</self_collide>
        <kinematic>0</kinematic>
        <gravity>1</gravity>
      </link>
      <link name='right_wheel'>
        <pose>0 -0.13 0.032 0 -0 0</pose>
        <inertial>
          <inertia>
            <ixx>0.001</ixx>
            <ixy>0</ixy>
            <ixz>0</ixz>
            <iyy>0.001</iyy>
            <iyz>0</iyz>
            <izz>0.001</izz>
          </inertia>
          <mass>0.01</mass>
        </inertial>
        <collision name='collision'>
          <pose>0 0 0 -5.76279e-13 1.5707 1.5707</pose>
          <geometry>
            <cylinder>
              <radius>0.033</radius>
              <length>0.023</length>
            </cylinder>
          </geometry>
          <surface>
            <friction>
              <ode>
                <mu>10</mu>
                <mu2>10</mu2>
                <fdir1>0 0 0</fdir1>
                <slip1>0</slip1>
                <slip2>0</slip2>
              </ode>
            </friction>
            <bounce/>
            <contact>
              <ode/>
            </contact>
          </surface>
          <max_contacts>10</max_contacts>
        </collision>
        <visual name='visual'>
          <pose>0 0 0 -5.76279e-13 1.5707 1.5707</pose>
          <geometry>
            <cylinder>
              <radius>0.033</radius>
              <length>0.023</length>
            </cylinder>
          </geometry>
        </visual>
        <velocity_decay>
          <linear>0</linear>
          <angular>0</angular>
        </velocity_decay>
        <self_collide>0</self_collide>
        <kinematic>0</kinematic>
        <gravity>1</gravity>
      </link>
      <joint name='left_wheel' type='revolute'>
        <parent>base</parent>
        <child>left_wheel</child>
        <axis>
          <xyz>0 1 0</xyz>
          <limit>
            <lower>-1e+16</lower>
            <upper>1e+16</upper>
          </limit>
        </axis>
      </joint>
      <joint name='right_wheel' type='revolute'>
        <parent>base</parent>
        <child>right_wheel</child>
        <axis>
          <xyz>0 1 0</xyz>
          <limit>
            <lower>-1e+16</lower>
            <upper>1e+16</upper>
          </limit>
        </axis>
      </joint>
      <link name='camera_sensor_left_link'>
        <pose>0.175 0.05 0.175 0 -0 0</pose>
        <inertial>
          <inertia>
            <ixx>1e-06</ixx>
            <ixy>0</ixy>
            <ixz>0</ixz>
            <iyy>1e-06</iyy>
            <iyz>0</iyz>
            <izz>1e-06</izz>
          </inertia>
          <mass>1e-05</mass>
        </inertial>
        <sensor name='camera_sensor_left' type='camera'>
          <update_rate>30</update_rate>
          <camera name='head'>
            <horizontal_fov>1.5708</horizontal_fov>
            <image>
              <width>640</width>
              <height>480</height>
              <format>R8G8B8</format>
            </image>
            <clip>
              <near>0.02</near>
              <far>300</far>
            </clip>
            <noise>
              <type>gaussian</type>
              <mean>0</mean>
              <stddev>0.007</stddev>
            </noise>
          </camera>
          <plugin name='camera_sensor_left_controller' filename='libgazebo_ros_camera.so'>
            <alwaysOn>true</alwaysOn>
            <updateRate>0.0</updateRate>
            <cameraName>stereo/left</cameraName>
            <imageTopicName>image_raw</imageTopicName>
            <cameraInfoTopicName>camera_info</cameraInfoTopicName>
            <frameName>camera_sensor_left_link</frameName>
            <hackBaseline>0.07</hackBaseline>
            <distortionK1>0.0</distortionK1>
            <distortionK2>0.0</distortionK2>
            <distortionK3>0.0</distortionK3>
            <distortionT1>0.0</distortionT1>
            <distortionT2>0.0</distortionT2>
            <blurSigma>0</blurSigma>
            <distortionSigma>0.0</distortionSigma>
          </plugin>
        </sensor>
        <velocity_decay>
          <linear>0</linear>
          <angular>0</angular>
        </velocity_decay>
        <self_collide>0</self_collide>
        <kinematic>0</kinematic>
        <gravity>1</gravity>
      </link>
      <joint name='camera_sensor_left_joint' type='revolute'>
        <parent>base</parent>
        <child>camera_sensor_left_link</child>
        <axis>
          <xyz>0.175 0.05 0.175</xyz>
          <limit>
            <upper>0</upper>
            <lower>0</lower>
          </limit>
        </axis>
      </joint>
      <link name='camera_sensor_right_link'>
        <pose>0.175 -0.05 0.175 0 -0 0</pose>
        <inertial>
          <inertia>
            <ixx>1e-06</ixx>
            <ixy>0</ixy>
            <ixz>0</ixz>
            <iyy>1e-06</iyy>
            <iyz>0</iyz>
            <izz>1e-06</izz>
          </inertia>
          <mass>1e-05</mass>
        </inertial>
        <sensor name='camera_sensor_right' type='camera'>
          <update_rate>30</update_rate>
          <camera name='head'>
            <horizontal_fov>1.5708</horizontal_fov>
            <image>
              <width>640</width>
              <height>480</height>
              <format>R8G8B8</format>
            </image>
            <clip>
              <near>0.02</near>
              <far>300</far>
            </clip>
            <noise>
              <type>gaussian</type>
              <mean>0</mean>
              <stddev>0.007</stddev>
            </noise>
          </camera>
          <plugin name='camera_sensor_right_controller' filename='libgazebo_ros_camera.so'>
            <alwaysOn>true</alwaysOn>
            <updateRate>0.0</updateRate>
            <cameraName>stereo/right</cameraName>
            <imageTopicName>image_raw</imageTopicName>
            <cameraInfoTopicName>camera_info</cameraInfoTopicName>
            <frameName>camera_sensor_right_link</frameName>
            <hackBaseline>0.07</hackBaseline>
            <distortionK1>0.0</distortionK1>
            <distortionK2>0.0</distortionK2>
            <distortionK3>0.0</distortionK3>
            <distortionT1>0.0</distortionT1>
            <distortionT2>0.0</distortionT2>
            <blurSigma>0</blurSigma>
            <distortionSigma>0.0</distortionSigma>
          </plugin>
        </sensor>
        <velocity_decay>
          <linear>0</linear>
          <angular>0</angular>
        </velocity_decay>
        <self_collide>0</self_collide>
        <kinematic>0</kinematic>
        <gravity>1</gravity>
      </link>
      <joint name='camera_sensor_right_joint' type='revolute'>
        <parent>base</parent>
        <child>camera_sensor_right_link</child>
        <axis>
          <xyz>0.175 -0.05 0.175</xyz>
          <limit>
            <upper>0</upper>
            <lower>0</lower>
          </limit>
        </axis>
      </joint>
      <link name='hokuyo_link'>
        <pose>0.05 0 0.11 0 -0 0</pose>
        <inertial>
          <inertia>
            <ixx>1e-06</ixx>
            <ixy>0</ixy>
            <ixz>0</ixz>
            <iyy>1e-06</iyy>
            <iyz>0</iyz>
            <izz>1e-06</izz>
          </inertia>
          <mass>1e-05</mass>
        </inertial>
        <collision name='collision'>
          <pose>0 0 0.5 0 -0 0</pose>
          <geometry>
            <box>
              <size>0.1 0.1 0.1</size>
            </box>
          </geometry>
          <max_contacts>10</max_contacts>
          <surface>
            <bounce/>
            <friction>
              <ode/>
            </friction>
            <contact>
              <ode/>
            </contact>
          </surface>
        </collision>
        <visual name='visual'>
          <geometry>
            <mesh>
              <uri>model://hokuyo/meshes/hokuyo.dae</uri>
            </mesh>
          </geometry>
        </visual>
        <sensor name='laser' type='ray'>
          <pose>0.01 0 0.0175 0 -0 0</pose>
          <ray>
            <scan>
              <horizontal>
                <samples>640</samples>
                <resolution>1</resolution>
                <min_angle>-2.26889</min_angle>
                <max_angle>2.2689</max_angle>
              </horizontal>
            </scan>
            <range>
              <min>0.08</min>
              <max>1</max>
              <resolution>0.01</resolution>
            </range>
          </ray>
          <plugin name='gazebo_ros_head_hokuyo_controller' filename='libgazebo_ros_laser.so'>
            <topicName>/scan</topicName>
            <frameName>base_footprint</frameName>
            <updateRate>15.0</updateRate>
            <robotNamespace>/</robotNamespace>
          </plugin>
          <always_on>1</always_on>
          <update_rate>30</update_rate>
          <visualize>1</visualize>
        </sensor>
        <velocity_decay>
          <linear>0</linear>
          <angular>0</angular>
        </velocity_decay>
        <self_collide>0</self_collide>
        <kinematic>0</kinematic>
        <gravity>1</gravity>
      </link>
      <joint name='hokuyo_joint' type='revolute'>
        <parent>base</parent>
        <child>hokuyo_link</child>
        <axis>
          <xyz>0 1 0</xyz>
          <limit>
            <upper>0</upper>
            <lower>0</lower>
          </limit>
        </axis>
      </joint>
      <plugin name='differential_drive_controller' filename='libgazebo_ros_diff_drive.so'>
        <alwaysOn>true</alwaysOn>
        <updateRate>100</updateRate>
        <update_rate>20</update_rate>
        <leftJoint>right_wheel</leftJoint>
        <rightJoint>left_wheel</rightJoint>
        <wheelSeparation>0.5380</wheelSeparation>
        <wheelDiameter>0.2410</wheelDiameter>
        <torque>20</torque>
        <commandTopic>cmd_vel</commandTopic>
        <odometryTopic>odomx</odometryTopic>
        <odometryFrame>odomx</odometryFrame>
        <robotBaseFrame>base_footprintx</robotBaseFrame>
        <robotNamespace>/</robotNamespace>
      </plugin>
      <pose>0 0 0 0 -0 0</pose>
      <static>0</static>
    </model>
    <model name='Dumpster'>
      <link name='link'>
        <collision name='collision'>
          <geometry>
            <mesh>
              <uri>model://dumpster/meshes/dumpster.dae</uri>
            </mesh>
          </geometry>
          <max_contacts>10</max_contacts>
          <surface>
            <bounce/>
            <friction>
              <ode/>
            </friction>
            <contact>
              <ode/>
            </contact>
          </surface>
        </collision>
        <visual name='visual'>
          <geometry>
            <mesh>
              <uri>model://dumpster/meshes/dumpster.dae</uri>
            </mesh>
          </geometry>
          <material>
            <script>
              <uri>model://dumpster/materials/scripts</uri>
              <uri>model://dumpster/materials/textures</uri>
              <name>Dumpster/Diffuse</name>
            </script>
          </material>
        </visual>
        <velocity_decay>
          <linear>0</linear>
          <angular>0</angular>
        </velocity_decay>
        <self_collide>0</self_collide>
        <inertial>
          <inertia>
            <ixx>1</ixx>
            <ixy>0</ixy>
            <ixz>0</ixz>
            <iyy>1</iyy>
            <iyz>0</iyz>
            <izz>1</izz>
          </inertia>
          <mass>1</mass>
        </inertial>
        <kinematic>0</kinematic>
        <gravity>1</gravity>
      </link>
      <pose>-6 3 0 0 -0 0</pose>
      <static>0</static>
    </model>
    <model name='grey_wall'>
      <static>1</static>
      <link name='link'>
        <pose>0 0 1.4 0 -0 0</pose>
        <collision name='collision'>
          <geometry>
            <box>
              <size>7.5 0.2 2.8</size>
            </box>
          </geometry>
          <max_contacts>10</max_contacts>
          <surface>
            <bounce/>
            <friction>
              <ode/>
            </friction>
            <contact>
              <ode/>
            </contact>
          </surface>
        </collision>
        <visual name='visual'>
          <cast_shadows>0</cast_shadows>
          <geometry>
            <box>
              <size>7.5 0.2 2.8</size>
            </box>
          </geometry>
          <material>
            <script>
              <uri>model://grey_wall/materials/scripts_the_last_supper</uri>
              <uri>model://grey_wall/materials/textures</uri>
              <name>vrc/grey_wall_The_Last_Supper</name>
            </script>
          </material>
        </visual>
        <velocity_decay>
          <linear>0</linear>
          <angular>0</angular>
        </velocity_decay>
        <self_collide>0</self_collide>
        <kinematic>0</kinematic>
        <gravity>1</gravity>
      </link>
      <pose>3 4 0 0 -0 0</pose>
    </model>
    <model name='grey_tote'>
      <link name='link'>
        <inertial>
          <pose>0 0 0.14155 0 -0 0</pose>
          <mass>3.53802</mass>
          <inertia>
            <ixx>0.0688358</ixx>
            <ixy>0</ixy>
            <ixz>0</ixz>
            <iyy>0.139596</iyy>
            <iyz>0</iyz>
            <izz>0.155909</izz>
          </inertia>
        </inertial>
        <collision name='lid'>
          <pose>0 0 0.28958 0 -0 0</pose>
          <geometry>
            <box>
              <size>0.67768 0.41298 0.01588</size>
            </box>
          </geometry>
          <max_contacts>10</max_contacts>
          <surface>
            <bounce/>
            <friction>
              <ode/>
            </friction>
            <contact>
              <ode/>
            </contact>
          </surface>
        </collision>
        <collision name='lid_lip_1'>
          <pose>0 0.20063 0.3048 0 -0 0</pose>
          <geometry>
            <box>
              <size>0.65068 0.0105 0.0127</size>
            </box>
          </geometry>
          <max_contacts>10</max_contacts>
          <surface>
            <bounce/>
            <friction>
              <ode/>
            </friction>
            <contact>
              <ode/>
            </contact>
          </surface>
        </collision>
        <collision name='lid_lip_2'>
          <pose>0 -0.20063 0.3048 0 -0 0</pose>
          <geometry>
            <box>
              <size>0.65068 0.0105 0.0127</size>
            </box>
          </geometry>
          <max_contacts>10</max_contacts>
          <surface>
            <bounce/>
            <friction>
              <ode/>
            </friction>
            <contact>
              <ode/>
            </contact>
          </surface>
        </collision>
        <collision name='lid_lip_3'>
          <pose>0.32585 0 0.3048 0 -0 0</pose>
          <geometry>
            <box>
              <size>0.02602 0.31202 0.0127</size>
            </box>
          </geometry>
          <max_contacts>10</max_contacts>
          <surface>
            <bounce/>
            <friction>
              <ode/>
            </friction>
            <contact>
              <ode/>
            </contact>
          </surface>
        </collision>
        <collision name='lid_lip_4'>
          <pose>-0.32585 0 0.3048 0 -0 0</pose>
          <geometry>
            <box>
              <size>0.02602 0.31202 0.0127</size>
            </box>
          </geometry>
          <max_contacts>10</max_contacts>
          <surface>
            <bounce/>
            <friction>
              <ode/>
            </friction>
            <contact>
              <ode/>
            </contact>
          </surface>
        </collision>
        <collision name='side_wall_1'>
          <pose>0 -0.18 0.14155 0.0611474 -0 0</pose>
          <geometry>
            <box>
              <size>0.58404 0.02602 0.283099</size>
            </box>
          </geometry>
          <max_contacts>10</max_contacts>
          <surface>
            <bounce/>
            <friction>
              <ode/>
            </friction>
            <contact>
              <ode/>
            </contact>
          </surface>
        </collision>
        <collision name='side_wall_2'>
          <pose>0 0.18 0.14155 -0.0611474 0 0</pose>
          <geometry>
            <box>
              <size>0.58404 0.02602 0.283099</size>
            </box>
          </geometry>
          <max_contacts>10</max_contacts>
          <surface>
            <bounce/>
            <friction>
              <ode/>
            </friction>
            <contact>
              <ode/>
            </contact>
          </surface>
        </collision>
        <collision name='side_wall_3'>
          <pose>0.305 0 0.14155 0 0.0611474 0</pose>
          <geometry>
            <box>
              <size>0.02602 0.33046 0.283099</size>
            </box>
          </geometry>
          <max_contacts>10</max_contacts>
          <surface>
            <bounce/>
            <friction>
              <ode/>
            </friction>
            <contact>
              <ode/>
            </contact>
          </surface>
        </collision>
        <collision name='side_wall_4'>
          <pose>-0.305 0 0.14155 0 -0.0611474 0</pose>
          <geometry>
            <box>
              <size>0.02602 0.33046 0.283099</size>
            </box>
          </geometry>
          <max_contacts>10</max_contacts>
          <surface>
            <bounce/>
            <friction>
              <ode/>
            </friction>
            <contact>
              <ode/>
            </contact>
          </surface>
        </collision>
        <collision name='bottom'>
          <pose>0 0 0.01 0 -0 0</pose>
          <geometry>
            <box>
              <size>0.58404 0.33046 0.02</size>
            </box>
          </geometry>
          <max_contacts>10</max_contacts>
          <surface>
            <bounce/>
            <friction>
              <ode/>
            </friction>
            <contact>
              <ode/>
            </contact>
          </surface>
        </collision>
        <collision name='corner_1'>
          <pose>0.30202 -0.175 0.14155 0.0611474 0.0611474 -4.34493e-19</pose>
          <geometry>
            <cylinder>
              <radius>0.01268</radius>
              <length>0.283099</length>
            </cylinder>
          </geometry>
          <max_contacts>10</max_contacts>
          <surface>
            <bounce/>
            <friction>
              <ode/>
            </friction>
            <contact>
              <ode/>
            </contact>
          </surface>
        </collision>
        <collision name='corner_2'>
          <pose>-0.30202 -0.175 0.14155 0.0611474 -0.0611474 4.34493e-19</pose>
          <geometry>
            <cylinder>
              <radius>0.01268</radius>
              <length>0.283099</length>
            </cylinder>
          </geometry>
          <max_contacts>10</max_contacts>
          <surface>
            <bounce/>
            <friction>
              <ode/>
            </friction>
            <contact>
              <ode/>
            </contact>
          </surface>
        </collision>
        <collision name='corner_3'>
          <pose>-0.30202 0.175 0.14155 -0.0611474 -0.0611474 -4.34493e-19</pose>
          <geometry>
            <cylinder>
              <radius>0.01268</radius>
              <length>0.283099</length>
            </cylinder>
          </geometry>
          <max_contacts>10</max_contacts>
          <surface>
            <bounce/>
            <friction>
              <ode/>
            </friction>
            <contact>
              <ode/>
            </contact>
          </surface>
        </collision>
        <collision name='corner_4'>
          <pose>0.30202 0.175 0.14155 -0.0611474 0.0611474 4.34493e-19</pose>
          <geometry>
            <cylinder>
              <radius>0.01268</radius>
              <length>0.283099</length>
            </cylinder>
          </geometry>
          <max_contacts>10</max_contacts>
          <surface>
            <bounce/>
            <friction>
              <ode/>
            </friction>
            <contact>
              <ode/>
            </contact>
          </surface>
        </collision>
        <visual name='visual'>
          <geometry>
            <mesh>
              <uri>model://grey_tote/meshes/tote.dae</uri>
            </mesh>
          </geometry>
        </visual>
        <velocity_decay>
          <linear>0</linear>
          <angular>0</angular>
        </velocity_decay>
        <self_collide>0</self_collide>
        <kinematic>0</kinematic>
        <gravity>1</gravity>
      </link>
      <pose>3 5.59113 0 0 -0 0</pose>
      <static>0</static>
    </model>
    <model name='grey_wall_0'>
      <static>1</static>
      <link name='link'>
        <pose>0 0 1.4 0 -0 0</pose>
        <collision name='collision'>
          <geometry>
            <box>
              <size>7.5 0.2 2.8</size>
            </box>
          </geometry>
          <max_contacts>10</max_contacts>
          <surface>
            <bounce/>
            <friction>
              <ode/>
            </friction>
            <contact>
              <ode/>
            </contact>
          </surface>
        </collision>
        <visual name='visual'>
          <cast_shadows>0</cast_shadows>
          <geometry>
            <box>
              <size>7.5 0.2 2.8</size>
            </box>
          </geometry>
          <material>
            <script>
              <uri>model://grey_wall/materials/scripts_Village_Street</uri>
              <uri>model://grey_wall/materials/textures</uri>
              <name>vrc/grey_wall_Village_Street</name>
            </script>
          </material>
        </visual>
        <velocity_decay>
          <linear>0</linear>
          <angular>0</angular>
        </velocity_decay>
        <self_collide>0</self_collide>
        <kinematic>0</kinematic>
        <gravity>1</gravity>
      </link>
      <pose>8 6 0 0 -0 0</pose>
    </model>
    <state world_name='default'>
      <sim_time>3758 569000000</sim_time>
      <real_time>29 99741323</real_time>
      <wall_time>1483458782 135070348</wall_time>
      <model name='Dumpster'>
        <pose>-6 3 0.000916 -8e-06 -0 -0</pose>
        <link name='link'>
          <pose>-6 3 0.000916 -8e-06 -0 -0</pose>
          <velocity>0 0 0 0 -0 0</velocity>
          <acceleration>0.00567 0.002945 -0.978483 3.07449 -0.128416 7e-06</acceleration>
          <wrench>0.00567 0.002945 -0.978483 0 -0 0</wrench>
        </link>
      </model>
      <model name='create'>
        <pose>-0.908404 -0.173244 0.000933 -9.1e-05 -0.000519 0.028919</pose>
        <link name='base'>
          <pose>-0.908404 -0.173244 0.000933 -9.1e-05 -0.000519 0.028919</pose>
          <velocity>-0.000143 0.000703 0.000299 0.02136 -0.000181 0.000943</velocity>
          <acceleration>-0.000865 -0.037379 0.886413 1.18063 0.022165 0.015754</acceleration>
          <wrench>-0.001932 -0.083504 1.98025 0 -0 0</wrench>
        </link>
        <link name='camera_sensor_left_link'>
          <pose>-0.735014 -0.118191 0.176018 -9.1e-05 -0.000518 0.028919</pose>
          <velocity>-0.000293 -0.002788 0.001627 0.020748 -0.000653 0.000909</velocity>
          <acceleration>0.045488 -6.39351 3.29483 -1.91251 0.030424 -0.006179</acceleration>
          <wrench>0 -6.4e-05 3.3e-05 0 -0 0</wrench>
        </link>
        <link name='camera_sensor_right_link'>
          <pose>-0.732123 -0.218149 0.176027 -9.2e-05 -0.000518 0.028919</pose>
          <velocity>-0.000199 -0.002785 -0.000448 0.020747 -0.000633 0.000909</velocity>
          <acceleration>0.045986 -6.39394 -1.08156 -1.91149 0.033948 -0.005061</acceleration>
          <wrench>0 -6.4e-05 -1.1e-05 0 -0 0</wrench>
        </link>
        <link name='hokuyo_link'>
          <pose>-0.858483 -0.17179 0.110958 -9.2e-05 -0.000519 0.028919</pose>
          <velocity>-0.000201 -0.001552 0.000434 0.02078 -0.000586 0.000943</velocity>
          <acceleration>0.024597 -3.54627 0.98881 -1.90628 0.045633 0.000492</acceleration>
          <wrench>0 -3.5e-05 1e-05 0 -0 0</wrench>
        </link>
        <link name='left_wheel'>
          <pose>-0.912179 -0.043299 0.03301 -0.000102 -0.00123 0.028919</pose>
          <velocity>-4.3e-05 -0.000626 0.019376 0.019492 -0.000784 0.000946</velocity>
          <acceleration>0.502738 -1.48039 40.7826 -2.17957 0.008161 0.001205</acceleration>
          <wrench>0.005027 -0.014804 0.407826 0 -0 0</wrench>
        </link>
        <link name='right_wheel'>
          <pose>-0.904662 -0.303184 0.032992 -9.8e-05 -0.000282 0.028919</pose>
          <velocity>-1.2e-05 -0.000609 -0.014284 0.02229 -0.000565 0.000943</velocity>
          <acceleration>0.029392 -1.40008 -28.6623 -1.604 0.038763 0.00049</acceleration>
          <wrench>0.000294 -0.014001 -0.286623 0 -0 0</wrench>
        </link>
      </model>
      <model name='grey_tote'>
        <pose>2.94008 4.94933 0.000566 0 -0 0</pose>
        <link name='link'>
          <pose>2.94008 4.94933 0.000566 0 -0 0</pose>
          <velocity>0 0 0 0 -0 0</velocity>
          <acceleration>-0 0 0 0 -0 0</acceleration>
          <wrench>-0 0 0 0 -0 0</wrench>
        </link>
      </model>
      <model name='grey_wall'>
        <pose>-1.34208 -0.60899 0 0 -0 1.56948</pose>
        <link name='link'>
          <pose>-1.34208 -0.60899 1.4 0 -0 1.56948</pose>
          <velocity>0 0 0 0 -0 0</velocity>
          <acceleration>0 0 0 0 -0 0</acceleration>
          <wrench>0 0 0 0 -0 0</wrench>
        </link>
      </model>
      <model name='grey_wall_0'>
        <pose>3.81178 2.98838 0 0 0 -1.58944</pose>
        <link name='link'>
          <pose>3.81178 2.98838 1.4 0 0 -1.58944</pose>
          <velocity>0 0 0 0 -0 0</velocity>
          <acceleration>0 0 0 0 -0 0</acceleration>
          <wrench>0 0 0 0 -0 0</wrench>
        </link>
      </model>
      <model name='grey_wall_1'>
        <pose>2.344 -0.808754 0 0 -0 0.025222</pose>
        <link name='link'>
          <pose>2.344 -0.808754 1.4 0 -0 0.025222</pose>
          <velocity>0 0 0 0 -0 0</velocity>
          <acceleration>0 0 0 0 -0 0</acceleration>
          <wrench>0 0 0 0 -0 0</wrench>
        </link>
      </model>
      <model name='grey_wall_2'>
        <pose>0.172013 3.22492 0 0 -0 0</pose>
        <link name='link'>
          <pose>0.172013 3.22492 1.4 0 -0 0</pose>
          <velocity>0 0 0 0 -0 0</velocity>
          <acceleration>0 0 0 0 -0 0</acceleration>
          <wrench>0 0 0 0 -0 0</wrench>
        </link>
      </model>
      <model name='ground_plane'>
        <pose>0 0 0 0 -0 0</pose>
        <link name='link'>
          <pose>0 0 0 0 -0 0</pose>
          <velocity>0 0 0 0 -0 0</velocity>
          <acceleration>0 0 0 0 -0 0</acceleration>
          <wrench>0 0 0 0 -0 0</wrench>
        </link>
      </model>
    </state>
    <gui fullscreen='0'>
      <camera name='user_camera'>
        <pose>0.454314 0.488653 13.3016 -1.2e-05 1.5698 -0.271847</pose>
        <view_controller>orbit</view_controller>
      </camera>
    </gui>
    <model name='grey_wall_1'>
      <static>1</static>
      <link name='link'>
        <pose>0 0 1.4 0 -0 0</pose>
        <collision name='collision'>
          <geometry>
            <box>
              <size>7.5 0.2 2.8</size>
            </box>
          </geometry>
          <max_contacts>10</max_contacts>
          <surface>
            <bounce/>
            <friction>
              <ode/>
            </friction>
            <contact>
              <ode/>
            </contact>
          </surface>
        </collision>
        <visual name='visual'>
          <cast_shadows>0</cast_shadows>
          <geometry>
            <box>
              <size>7.5 0.2 2.8</size>
            </box>
          </geometry>
          <material>
            <script>
              <uri>model://grey_wall/materials/scripts_women_of_algiers</uri>
              <uri>model://grey_wall/materials/textures</uri>
              <name>vrc/grey_wall_women_of_algiers</name>
            </script>
          </material>
        </visual>
        <velocity_decay>
          <linear>0</linear>
          <angular>0</angular>
        </velocity_decay>
        <self_collide>0</self_collide>
        <kinematic>0</kinematic>
        <gravity>1</gravity>
      </link>
      <pose>0 -1 0 0 -0 0</pose>
    </model>
    <model name='grey_wall_2'>
      <static>1</static>
      <link name='link'>
        <pose>0 0 1.4 0 -0 0</pose>
        <collision name='collision'>
          <geometry>
            <box>
              <size>7.5 0.2 2.8</size>
            </box>
          </geometry>
          <max_contacts>10</max_contacts>
          <surface>
            <bounce/>
            <friction>
              <ode/>
            </friction>
            <contact>
              <ode/>
            </contact>
          </surface>
        </collision>
        <visual name='visual'>
          <cast_shadows>0</cast_shadows>
          <geometry>
            <box>
              <size>7.5 0.2 2.8</size>
            </box>
          </geometry>
          <material>
            <script>
              <uri>model://grey_wall/materials/scripts</uri>
              <uri>model://grey_wall/materials/textures</uri>
              <name>vrc/grey_wall</name>
            </script>
          </material>
        </visual>
        <velocity_decay>
          <linear>0</linear>
          <angular>0</angular>
        </velocity_decay>
        <self_collide>0</self_collide>
        <kinematic>0</kinematic>
        <gravity>1</gravity>
      </link>
      <pose>2.49613 3.40598 0 0 -0 0</pose>
    </model>
  </world>
</sdf>
